<?xml version="1.0" ?>
<!-- =================================================================================== -->
<!-- |    This document was autogenerated by xacro from vp6242.urdf.xacro              | -->
<!-- |    EDITING THIS FILE BY HAND IS NOT RECOMMENDED                                 | -->
<!-- =================================================================================== -->
<robot name="vp6242" xmlns:xacro="http://www.ros.org/wiki/xacro">
  <!--
		J1   J2   J3   J4   J5   J6
		160  120  160  160  120  360
	   -160 -120   19 -160 -120 -360
	-->
  <!-- As acceleration limit -->
  <link name="base_link">
    <visual>
      <geometry>
        <mesh filename="package://vp6242_description/robot/base.dae" scale="0.001 0.001 0.001"/>
      </geometry>
      <origin rpy="-1.570796 3.141592 0" xyz="0 0 0"/>
      <material name="base_link">
        <color rgba="0.3 0.4 0.8 1"/>
      </material>
    </visual>
    <collision>
      <geometry>
        <mesh filename="package://vp6242_description/robot/base_collision.dae" scale="0.001 0.001 0.001"/>
      </geometry>
      <origin rpy="-1.570796 3.141592 0" xyz="0 0 0"/>
    </collision>
  </link>
  <link name="link0">
    <visual>
      <geometry>
        <mesh filename="package://vp6242_description/robot/l0.dae" scale="0.001 0.001 0.001"/>
      </geometry>
      <origin rpy="-1.570796 3.141592 0" xyz="0 0 0"/>
      <material name="link">
        <color rgba="0.8 0.8 0.8 1"/>
      </material>
    </visual>
    <collision>
      <geometry>
        <mesh filename="package://vp6242_description/robot/l0_collision.dae" scale="0.001 0.001 0.001"/>
      </geometry>
      <origin rpy="-1.570796 3.141592 0" xyz="0 0 0"/>
    </collision>
  </link>
  <joint name="J1" type="revolute">
    <axis xyz="0 0 1"/>
    <limit effort="1.0" lower="-2.79252680319" upper="2.79252680319" velocity="1.0"/>
    <origin rpy="0 0 0" xyz="0.0 0.0 0.155"/>
    <parent link="base_link"/>
    <child link="link0"/>
  </joint>
  <link name="link1">
    <visual>
      <geometry>
        <mesh filename="package://vp6242_description/robot/l1.dae" scale="0.001 0.001 0.001"/>
      </geometry>
      <origin rpy="-1.570796 3.141592 0" xyz="0 0 0"/>
      <material name="link"/>
    </visual>
    <collision>
      <geometry>
        <mesh filename="package://vp6242_description/robot/l1_collision.dae" scale="0.001 0.001 0.001"/>
      </geometry>
      <origin rpy="-1.570796 3.141592 0" xyz="0 0 0"/>
    </collision>
  </link>
  <joint name="J2" type="revolute">
    <axis xyz="0 1 0"/>
    <limit effort="1.0" lower="-2.09439510239" upper="2.09439510239" velocity="1.0"/>
    <origin rpy="0 0 0" xyz="0.0 0.0 0.125"/>
    <parent link="link0"/>
    <child link="link1"/>
  </joint>
  <link name="link2">
    <visual>
      <geometry>
        <mesh filename="package://vp6242_description/robot/l2.dae" scale="0.001 0.001 0.001"/>
      </geometry>
      <origin rpy="-1.570796 1.570796 0" xyz="0 0 0"/>
      <material name="link"/>
    </visual>
    <collision>
      <geometry>
        <mesh filename="package://vp6242_description/robot/l2_collision.dae" scale="0.001 0.001 0.001"/>
      </geometry>
      <origin rpy="-1.570796 1.570796 0" xyz="0 0 0"/>
    </collision>
  </link>
  <joint name="J3" type="revolute">
    <axis xyz="0 1 0"/>
    <limit effort="1.0" lower="0.331612557879" upper="2.79252680319" velocity="1.0"/>
    <origin rpy="0 0 0" xyz="0.0 0.0 0.210"/>
    <parent link="link1"/>
    <child link="link2"/>
  </joint>
  <link name="link3">
    <visual>
      <geometry>
        <mesh filename="package://vp6242_description/robot/l3.dae" scale="0.001 0.001 0.001"/>
      </geometry>
      <origin rpy="0 1.570796 1.570796" xyz="0 0 0.085"/>
      <material name="link"/>
    </visual>
    <collision>
      <geometry>
        <mesh filename="package://vp6242_description/robot/l3_collision.dae" scale="0.001 0.001 0.001"/>
      </geometry>
      <origin rpy="0 1.570796 1.570796" xyz="0 0 0.085"/>
    </collision>
  </link>
  <joint name="J4" type="revolute">
    <axis xyz="0 0 1"/>
    <limit effort="1.0" lower="-2.79252680319" upper="2.79252680319" velocity="1.0"/>
    <origin rpy="0 0 0" xyz="-0.075 0.0 0.0"/>
    <parent link="link2"/>
    <child link="link3"/>
  </joint>
  <link name="link4">
    <visual>
      <geometry>
        <mesh filename="package://vp6242_description/robot/l4.dae" scale="0.001 0.001 0.001"/>
      </geometry>
      <origin rpy="0 1.570796 1.570796" xyz="0 0 0.0"/>
      <material name="link"/>
    </visual>
    <collision>
      <geometry>
        <mesh filename="package://vp6242_description/robot/l4_collision.dae" scale="0.001 0.001 0.001"/>
      </geometry>
      <origin rpy="0 1.570796 1.570796" xyz="0 0 0.0"/>
    </collision>
  </link>
  <joint name="J5" type="revolute">
    <axis xyz="0 1 0"/>
    <limit effort="1.0" lower="-2.09439510239" upper="2.09439510239" velocity="1.0"/>
    <origin rpy="0 0 0" xyz="0.0 0.0 0.210"/>
    <parent link="link3"/>
    <child link="link4"/>
  </joint>
  <link name="link5">
    <visual>
      <geometry>
        <cylinder length="0.01" radius="0.0205"/>
      </geometry>
      <origin rpy="0 -1.570796 0" xyz="0.0 0.0 0.0"/>
      <material name="plate">
        <color rgba="0.1 0.1 0.1 0.8"/>
      </material>
    </visual>
  </link>
  <joint name="J6" type="revolute">
    <axis xyz="1 0 0"/>
    <limit effort="1.0" lower="-6.28318530718" upper="6.28318530718" velocity="1.0"/>
    <origin rpy="0 -1.570796 0" xyz="0.0 0.0 0.07"/>
    <parent link="link4"/>
    <child link="link5"/>
  </joint>
</robot>

